{"schemaVersion":{"minor":3,"major":0,"patch":0},"kind":"symbol","sections":[],"abstract":[{"text":"An error giving details of the reason synchronization failed.","type":"text"},{"text":" ","type":"text"},{"type":"text","text":"Only available for ‘partial’ synchronization state"}],"primaryContentSections":[{"declarations":[{"tokens":[{"text":"let","kind":"keyword"},{"text":" ","kind":"text"},{"kind":"identifier","text":"error"},{"text":": ","kind":"text"},{"kind":"typeIdentifier","identifier":"doc:\/\/me.digi.sdk.example.librarycore.DigiMeCore\/documentation\/DigiMeCore\/SyncError","text":"SyncError","preciseIdentifier":"s:10DigiMeCore9SyncErrorV"},{"kind":"text","text":"?"}],"languages":["swift"],"platforms":["iOS"]}],"kind":"declarations"}],"variants":[{"paths":["\/documentation\/digimecore\/syncaccount\/error"],"traits":[{"interfaceLanguage":"swift"}]}],"hierarchy":{"paths":[["doc:\/\/me.digi.sdk.example.librarycore.DigiMeCore\/documentation\/DigiMeCore","doc:\/\/me.digi.sdk.example.librarycore.DigiMeCore\/documentation\/DigiMeCore\/SyncAccount"]]},"metadata":{"externalID":"s:10DigiMeCore11SyncAccountV5errorAA0D5ErrorVSgvp","role":"symbol","symbolKind":"property","fragments":[{"text":"let","kind":"keyword"},{"text":" ","kind":"text"},{"kind":"identifier","text":"error"},{"kind":"text","text":": "},{"text":"SyncError","kind":"typeIdentifier","preciseIdentifier":"s:10DigiMeCore9SyncErrorV"},{"kind":"text","text":"?"}],"title":"error","roleHeading":"Instance Property","modules":[{"name":"DigiMeCore"}]},"identifier":{"interfaceLanguage":"swift","url":"doc:\/\/me.digi.sdk.example.librarycore.DigiMeCore\/documentation\/DigiMeCore\/SyncAccount\/error"},"references":{"doc://me.digi.sdk.example.librarycore.DigiMeCore/documentation/DigiMeCore/SyncAccount/error":{"role":"symbol","identifier":"doc:\/\/me.digi.sdk.example.librarycore.DigiMeCore\/documentation\/DigiMeCore\/SyncAccount\/error","kind":"symbol","url":"\/documentation\/digimecore\/syncaccount\/error","type":"topic","abstract":[{"text":"An error giving details of the reason synchronization failed.","type":"text"},{"type":"text","text":" "},{"text":"Only available for ‘partial’ synchronization state","type":"text"}],"fragments":[{"kind":"keyword","text":"let"},{"text":" ","kind":"text"},{"kind":"identifier","text":"error"},{"kind":"text","text":": "},{"preciseIdentifier":"s:10DigiMeCore9SyncErrorV","kind":"typeIdentifier","text":"SyncError"},{"kind":"text","text":"?"}],"title":"error"},"doc://me.digi.sdk.example.librarycore.DigiMeCore/documentation/DigiMeCore/SyncAccount":{"title":"SyncAccount","role":"symbol","url":"\/documentation\/digimecore\/syncaccount","identifier":"doc:\/\/me.digi.sdk.example.librarycore.DigiMeCore\/documentation\/DigiMeCore\/SyncAccount","navigatorTitle":[{"kind":"identifier","text":"SyncAccount"}],"kind":"symbol","type":"topic","abstract":[{"text":"Details of a source being synchronized","type":"text"}],"fragments":[{"kind":"keyword","text":"struct"},{"kind":"text","text":" "},{"kind":"identifier","text":"SyncAccount"}]},"doc://me.digi.sdk.example.librarycore.DigiMeCore/documentation/DigiMeCore/SyncError":{"url":"\/documentation\/digimecore\/syncerror","abstract":[{"text":"Reason why connecting to source or importing data from source into user’s library failed","type":"text"}],"role":"symbol","type":"topic","title":"SyncError","kind":"symbol","navigatorTitle":[{"text":"SyncError","kind":"identifier"}],"fragments":[{"text":"struct","kind":"keyword"},{"kind":"text","text":" "},{"text":"SyncError","kind":"identifier"}],"identifier":"doc:\/\/me.digi.sdk.example.librarycore.DigiMeCore\/documentation\/DigiMeCore\/SyncError"},"doc://me.digi.sdk.example.librarycore.DigiMeCore/documentation/DigiMeCore":{"type":"topic","identifier":"doc:\/\/me.digi.sdk.example.librarycore.DigiMeCore\/documentation\/DigiMeCore","abstract":[],"url":"\/documentation\/digimecore","title":"DigiMeCore","role":"collection","kind":"symbol"}}}