{"kind":"symbol","hierarchy":{"paths":[["doc:\/\/me.digi.sdk.example.librarycore.DigiMeCore\/documentation\/DigiMeCore","doc:\/\/me.digi.sdk.example.librarycore.DigiMeCore\/documentation\/DigiMeCore\/SyncAccount"]]},"schemaVersion":{"patch":0,"major":0,"minor":3},"abstract":[{"text":"An error giving details of the reason synchronization failed.","type":"text"},{"type":"text","text":" "},{"type":"text","text":"Only available for ‘partial’ synchronization state"}],"primaryContentSections":[{"declarations":[{"languages":["swift"],"platforms":["iOS"],"tokens":[{"kind":"keyword","text":"let"},{"text":" ","kind":"text"},{"text":"error","kind":"identifier"},{"text":": ","kind":"text"},{"text":"SyncError","preciseIdentifier":"s:10DigiMeCore9SyncErrorV","identifier":"doc:\/\/me.digi.sdk.example.librarycore.DigiMeCore\/documentation\/DigiMeCore\/SyncError","kind":"typeIdentifier"},{"kind":"text","text":"?"}]}],"kind":"declarations"}],"identifier":{"url":"doc:\/\/me.digi.sdk.example.librarycore.DigiMeCore\/documentation\/DigiMeCore\/SyncAccount\/error","interfaceLanguage":"swift"},"variants":[{"traits":[{"interfaceLanguage":"swift"}],"paths":["\/documentation\/digimecore\/syncaccount\/error"]}],"metadata":{"symbolKind":"property","role":"symbol","modules":[{"name":"DigiMeCore"}],"fragments":[{"kind":"keyword","text":"let"},{"text":" ","kind":"text"},{"text":"error","kind":"identifier"},{"kind":"text","text":": "},{"text":"SyncError","kind":"typeIdentifier","preciseIdentifier":"s:10DigiMeCore9SyncErrorV"},{"text":"?","kind":"text"}],"roleHeading":"Instance Property","externalID":"s:10DigiMeCore11SyncAccountV5errorAA0D5ErrorVSgvp","title":"error"},"sections":[],"references":{"doc://me.digi.sdk.example.librarycore.DigiMeCore/documentation/DigiMeCore/SyncAccount/error":{"url":"\/documentation\/digimecore\/syncaccount\/error","type":"topic","fragments":[{"text":"let","kind":"keyword"},{"kind":"text","text":" "},{"text":"error","kind":"identifier"},{"text":": ","kind":"text"},{"kind":"typeIdentifier","preciseIdentifier":"s:10DigiMeCore9SyncErrorV","text":"SyncError"},{"kind":"text","text":"?"}],"title":"error","abstract":[{"type":"text","text":"An error giving details of the reason synchronization failed."},{"text":" ","type":"text"},{"type":"text","text":"Only available for ‘partial’ synchronization state"}],"kind":"symbol","role":"symbol","identifier":"doc:\/\/me.digi.sdk.example.librarycore.DigiMeCore\/documentation\/DigiMeCore\/SyncAccount\/error"},"doc://me.digi.sdk.example.librarycore.DigiMeCore/documentation/DigiMeCore/SyncAccount":{"url":"\/documentation\/digimecore\/syncaccount","title":"SyncAccount","role":"symbol","navigatorTitle":[{"kind":"identifier","text":"SyncAccount"}],"type":"topic","abstract":[{"type":"text","text":"Details of a source being synchronized"}],"kind":"symbol","identifier":"doc:\/\/me.digi.sdk.example.librarycore.DigiMeCore\/documentation\/DigiMeCore\/SyncAccount","fragments":[{"kind":"keyword","text":"struct"},{"text":" ","kind":"text"},{"kind":"identifier","text":"SyncAccount"}]},"doc://me.digi.sdk.example.librarycore.DigiMeCore/documentation/DigiMeCore":{"title":"DigiMeCore","url":"\/documentation\/digimecore","type":"topic","kind":"symbol","role":"collection","identifier":"doc:\/\/me.digi.sdk.example.librarycore.DigiMeCore\/documentation\/DigiMeCore","abstract":[]},"doc://me.digi.sdk.example.librarycore.DigiMeCore/documentation/DigiMeCore/SyncError":{"type":"topic","title":"SyncError","role":"symbol","url":"\/documentation\/digimecore\/syncerror","abstract":[{"text":"Reason why connecting to source or importing data from source into user’s library failed","type":"text"}],"kind":"symbol","fragments":[{"text":"struct","kind":"keyword"},{"text":" ","kind":"text"},{"text":"SyncError","kind":"identifier"}],"navigatorTitle":[{"text":"SyncError","kind":"identifier"}],"identifier":"doc:\/\/me.digi.sdk.example.librarycore.DigiMeCore\/documentation\/DigiMeCore\/SyncError"}}}