{"variants":[{"paths":["\/documentation\/digimecore\/syncaccount\/error"],"traits":[{"interfaceLanguage":"swift"}]}],"schemaVersion":{"major":0,"patch":0,"minor":3},"identifier":{"interfaceLanguage":"swift","url":"doc:\/\/me.digi.sdk.example.librarycore.DigiMeCore\/documentation\/DigiMeCore\/SyncAccount\/error"},"primaryContentSections":[{"kind":"declarations","declarations":[{"platforms":["iOS"],"tokens":[{"kind":"keyword","text":"let"},{"kind":"text","text":" "},{"text":"error","kind":"identifier"},{"text":": ","kind":"text"},{"kind":"typeIdentifier","text":"SyncError","identifier":"doc:\/\/me.digi.sdk.example.librarycore.DigiMeCore\/documentation\/DigiMeCore\/SyncError","preciseIdentifier":"s:10DigiMeCore9SyncErrorV"},{"text":"?","kind":"text"}],"languages":["swift"]}]}],"hierarchy":{"paths":[["doc:\/\/me.digi.sdk.example.librarycore.DigiMeCore\/documentation\/DigiMeCore","doc:\/\/me.digi.sdk.example.librarycore.DigiMeCore\/documentation\/DigiMeCore\/SyncAccount"]]},"sections":[],"metadata":{"symbolKind":"property","modules":[{"name":"DigiMeCore"}],"roleHeading":"Instance Property","fragments":[{"text":"let","kind":"keyword"},{"kind":"text","text":" "},{"text":"error","kind":"identifier"},{"text":": ","kind":"text"},{"text":"SyncError","kind":"typeIdentifier","preciseIdentifier":"s:10DigiMeCore9SyncErrorV"},{"text":"?","kind":"text"}],"role":"symbol","title":"error","externalID":"s:10DigiMeCore11SyncAccountV5errorAA0D5ErrorVSgvp"},"kind":"symbol","abstract":[{"type":"text","text":"An error giving details of the reason synchronization failed."},{"text":" ","type":"text"},{"type":"text","text":"Only available for ‘partial’ synchronization state"}],"references":{"doc://me.digi.sdk.example.librarycore.DigiMeCore/documentation/DigiMeCore/SyncAccount/error":{"url":"\/documentation\/digimecore\/syncaccount\/error","fragments":[{"text":"let","kind":"keyword"},{"text":" ","kind":"text"},{"kind":"identifier","text":"error"},{"kind":"text","text":": "},{"kind":"typeIdentifier","text":"SyncError","preciseIdentifier":"s:10DigiMeCore9SyncErrorV"},{"kind":"text","text":"?"}],"role":"symbol","identifier":"doc:\/\/me.digi.sdk.example.librarycore.DigiMeCore\/documentation\/DigiMeCore\/SyncAccount\/error","title":"error","abstract":[{"text":"An error giving details of the reason synchronization failed.","type":"text"},{"type":"text","text":" "},{"text":"Only available for ‘partial’ synchronization state","type":"text"}],"type":"topic","kind":"symbol"},"doc://me.digi.sdk.example.librarycore.DigiMeCore/documentation/DigiMeCore/SyncAccount":{"title":"SyncAccount","identifier":"doc:\/\/me.digi.sdk.example.librarycore.DigiMeCore\/documentation\/DigiMeCore\/SyncAccount","role":"symbol","fragments":[{"kind":"keyword","text":"struct"},{"text":" ","kind":"text"},{"text":"SyncAccount","kind":"identifier"}],"url":"\/documentation\/digimecore\/syncaccount","kind":"symbol","abstract":[{"text":"Details of a source being synchronized","type":"text"}],"type":"topic","navigatorTitle":[{"text":"SyncAccount","kind":"identifier"}]},"doc://me.digi.sdk.example.librarycore.DigiMeCore/documentation/DigiMeCore":{"title":"DigiMeCore","identifier":"doc:\/\/me.digi.sdk.example.librarycore.DigiMeCore\/documentation\/DigiMeCore","abstract":[],"kind":"symbol","type":"topic","role":"collection","url":"\/documentation\/digimecore"},"doc://me.digi.sdk.example.librarycore.DigiMeCore/documentation/DigiMeCore/SyncError":{"role":"symbol","abstract":[{"text":"Reason why connecting to source or importing data from source into user’s library failed","type":"text"}],"type":"topic","url":"\/documentation\/digimecore\/syncerror","navigatorTitle":[{"text":"SyncError","kind":"identifier"}],"kind":"symbol","fragments":[{"text":"struct","kind":"keyword"},{"kind":"text","text":" "},{"text":"SyncError","kind":"identifier"}],"title":"SyncError","identifier":"doc:\/\/me.digi.sdk.example.librarycore.DigiMeCore\/documentation\/DigiMeCore\/SyncError"}}}