{"abstract":[{"type":"text","text":"An error giving details of the reason synchronization failed."},{"text":" ","type":"text"},{"type":"text","text":"Only available for ‘partial’ synchronization state"}],"identifier":{"url":"doc:\/\/me.digi.sdk.example.librarycore.DigiMeCore\/documentation\/DigiMeCore\/SyncAccount\/error","interfaceLanguage":"swift"},"schemaVersion":{"patch":0,"minor":3,"major":0},"sections":[],"metadata":{"roleHeading":"Instance Property","externalID":"s:10DigiMeCore11SyncAccountV5errorAA0D5ErrorVSgvp","modules":[{"name":"DigiMeCore"}],"role":"symbol","fragments":[{"kind":"keyword","text":"let"},{"text":" ","kind":"text"},{"kind":"identifier","text":"error"},{"kind":"text","text":": "},{"kind":"typeIdentifier","preciseIdentifier":"s:10DigiMeCore9SyncErrorV","text":"SyncError"},{"kind":"text","text":"?"}],"title":"error","symbolKind":"property"},"kind":"symbol","hierarchy":{"paths":[["doc:\/\/me.digi.sdk.example.librarycore.DigiMeCore\/documentation\/DigiMeCore","doc:\/\/me.digi.sdk.example.librarycore.DigiMeCore\/documentation\/DigiMeCore\/SyncAccount"]]},"primaryContentSections":[{"declarations":[{"platforms":["iOS"],"tokens":[{"text":"let","kind":"keyword"},{"text":" ","kind":"text"},{"text":"error","kind":"identifier"},{"text":": ","kind":"text"},{"preciseIdentifier":"s:10DigiMeCore9SyncErrorV","kind":"typeIdentifier","text":"SyncError","identifier":"doc:\/\/me.digi.sdk.example.librarycore.DigiMeCore\/documentation\/DigiMeCore\/SyncError"},{"text":"?","kind":"text"}],"languages":["swift"]}],"kind":"declarations"}],"variants":[{"traits":[{"interfaceLanguage":"swift"}],"paths":["\/documentation\/digimecore\/syncaccount\/error"]}],"references":{"doc://me.digi.sdk.example.librarycore.DigiMeCore/documentation/DigiMeCore/SyncError":{"type":"topic","role":"symbol","url":"\/documentation\/digimecore\/syncerror","abstract":[{"text":"Reason why connecting to source or importing data from source into user’s library failed","type":"text"}],"identifier":"doc:\/\/me.digi.sdk.example.librarycore.DigiMeCore\/documentation\/DigiMeCore\/SyncError","navigatorTitle":[{"text":"SyncError","kind":"identifier"}],"title":"SyncError","kind":"symbol","fragments":[{"kind":"keyword","text":"struct"},{"text":" ","kind":"text"},{"text":"SyncError","kind":"identifier"}]},"doc://me.digi.sdk.example.librarycore.DigiMeCore/documentation/DigiMeCore/SyncAccount/error":{"url":"\/documentation\/digimecore\/syncaccount\/error","title":"error","identifier":"doc:\/\/me.digi.sdk.example.librarycore.DigiMeCore\/documentation\/DigiMeCore\/SyncAccount\/error","type":"topic","fragments":[{"text":"let","kind":"keyword"},{"text":" ","kind":"text"},{"text":"error","kind":"identifier"},{"kind":"text","text":": "},{"preciseIdentifier":"s:10DigiMeCore9SyncErrorV","text":"SyncError","kind":"typeIdentifier"},{"kind":"text","text":"?"}],"kind":"symbol","role":"symbol","abstract":[{"text":"An error giving details of the reason synchronization failed.","type":"text"},{"type":"text","text":" "},{"text":"Only available for ‘partial’ synchronization state","type":"text"}]},"doc://me.digi.sdk.example.librarycore.DigiMeCore/documentation/DigiMeCore/SyncAccount":{"url":"\/documentation\/digimecore\/syncaccount","title":"SyncAccount","identifier":"doc:\/\/me.digi.sdk.example.librarycore.DigiMeCore\/documentation\/DigiMeCore\/SyncAccount","type":"topic","fragments":[{"text":"struct","kind":"keyword"},{"kind":"text","text":" "},{"text":"SyncAccount","kind":"identifier"}],"kind":"symbol","role":"symbol","navigatorTitle":[{"kind":"identifier","text":"SyncAccount"}],"abstract":[{"text":"Details of a source being synchronized","type":"text"}]},"doc://me.digi.sdk.example.librarycore.DigiMeCore/documentation/DigiMeCore":{"type":"topic","kind":"symbol","title":"DigiMeCore","identifier":"doc:\/\/me.digi.sdk.example.librarycore.DigiMeCore\/documentation\/DigiMeCore","abstract":[{"type":"text","text":"Summary"}],"url":"\/documentation\/digimecore","role":"collection"}}}